# Errors and Exceptions

ref

https://docs.python.org/3/tutorial/errors.html

## 8.1 Syntax Errors

也被称为 parsing errors
```bash
while True print('Hello world')
  File "<stdin>", line 1
    while True print('Hello world')
                   ^
SyntaxError: invalid syntax
```
## 8.2 Exceptions
即便是语法正确，也会导致报错，这种在运行中的错误叫做 exceptions，例如
```bash
>>> 10*(1/0)
Traceback (most recent call last):
  File "<stdin>", line 1, in <module>
ZeroDivisionError: division by zero
>>> 4+spam*3
Traceback (most recent call last):
  File "<stdin>", line 1, in <module>
NameError: name 'spam' is not defined
>>> '2'+2
Traceback (most recent call last):
  File "<stdin>", line 1, in <module>
TypeError: can only concatenate str (not "int") to str
```
最后一样表示发生了是吗，`ZeroDivisionError`，`NameError`，`TypeError` 都是 exception type，同行剩余的内容是导致错误的原因，上一行是错误出现的位置，其他部分都是 stack traceback
## 8.3 Handling Exception 
```bash
while True:
    try:
        x = int(input("Please enter a number: "))
        break
    except ValueError:
        print("Oops!  That was no valid number.  Try again...")
```

- 首先会执行 `try...except`中的内容
- 如果没有错误，`except`就会跳过
- 如果有错误且匹配 `except` 后的 exception type，`try`中剩余的部分就会跳过，然后执行 `except`中的内容
- 如果有错误但是不匹配 `except` 后的 exception type，`try`中剩余的部分就会跳过，同时 `except`中的内容也跳过，错误直接抛出

`except` 可以捕获多种 exception type
```bash
... except (RuntimeError, TypeError, NameError):
...     pass
```
exception 有继承关系，如果需要 `except`注意继承关系
```bash
class B(Exception):
    pass

class C(B):
    pass

class D(C):
    pass

for cls in [B, C, D]:
    try:
        raise cls()
    except D:
        print("D")
    except C:
        print("C")
    except B:
        print("B")
```
如果将 `except B`置于 `C` 和 `D` 之前 就会直接输出 `B\nB\nB` 而不是 `D\nC\nB`
可以使用 `__str()__` 或者 `args` 输出异常的入参
```bash
try:
    raise Exception('spam', 'eggs')
except Exception as inst:
    print(type(inst))    # the exception instance
    print(inst.args)     # arguments stored in .args
    print(inst)          # __str__ allows args to be printed directly,
                         # but may be overridden in exception subclasses
    x, y = inst.args     # unpack args
    print('x =', x)
    print('y =', y)
```
`BaseException`是所以 exception 的父类，`Exception`是所有 non-exit/non-fatal exception 的父类
`Exception` 可以作为 wildcard 匹配所以的异常
```bash
import sys

try:
    f = open('myfile.txt')
    s = f.readline()
    i = int(s.strip())
except OSError as err:
    print("OS error:", err)
except ValueError:
    print("Could not convert data to an integer.")
except Exception as err:
    print(f"Unexpected {err=}, {type(err)=}")
    raise
```
`try...except`还可以结合 `else`一起使用，表示如果没有报错则运行 `else`中的内容
```bash
if __name__ == '__main__':
    try:
        a = 1 / 0
    except Exception as e:
        print(f'{e.__str__()=}') 
    else:
        print('else clause')
#output
e.__str__()='division by zero'

if __name__ == '__main__':
    try:
        a = 1 / 1
    except Exception as e:
        print(f'{e.__str__()=}') 
    else:
        print('else clause')
#output
else clause
```
Exception 只有在被触发时才会调用
```bash
def this_fails():
    x = 1/0

try:
    this_fails()
except ZeroDivisionError as err:
    print('Handling run-time error:', err)

Handling run-time error: division by zero
```
## 8.4 Raising Exceptions
强制抛出异常
```bash
>>> raise NameError('HiThere')
Traceback (most recent call last):
  File "<stdin>", line 1, in <module>
NameError: HiThere
```
raise 的必须是 `Exception` class 或者是 `BaseException` class，如果只使用了 Exception，会隐式的调用空构造函数
```bash
raise ValueError  # shorthand for 'raise ValueError()'
```
如果想处理异常的同时，抛出异常，可以 re-raise
```bash
>>> try:
...     raise NameError('HiThere')
... except NameError:
...     print('An exception flew by!')
...     raise
...
An exception flew by!
Traceback (most recent call last):
  File "<stdin>", line 2, in <module>
NameError: HiThere
```
## 8.5 Exception Chaining
如果在 except 中报错了，exception 会逐级抛出
```bash
>>> try:
...     open("database.sqlite")
... except OSError:
...     raise RuntimeError("unable to handle error")
...
Traceback (most recent call last):
  File "<stdin>", line 2, in <module>
FileNotFoundError: [Errno 2] No such file or directory: 'database.sqlite'

During handling of the above exception, another exception occurred:

Traceback (most recent call last):
  File "<stdin>", line 4, in <module>
RuntimeError: unable to handle error
```
如果需要指定一个 Exception 是由另外一个 Exception 抛出的，可以
```bash
def func():
    raise ConnectionError
try:
    func()
except ConnectionError as exc:
    raise RuntimeError('Failed to open database') from exc
```
## 8.6 User-defined Exceptions
可以继承 `BaseException`或者 `Exception` 来自定义异常类
## 8.7 Defining Clean-up Actions
和其他的编程语言一样，Python 也有 `try...finally`，先执行 `try`，然后执行 `finally`，然后执行 `except`
```bash
>>> try:
...     raise KeyboardInterrupt
... finally:
...     print('Goodbye, world!')
...
Goodbye, world!
Traceback (most recent call last):
  File "<stdin>", line 2, in <module>
KeyboardInterrupt
```

- 如果`try`中报错，没有对应的 `except`，就会先执行 `finally`中的内容，然后抛出异常
- 如果`try`中报错，有对应的 `except` 或者 `else`，同时 `except` 或者 `else` 中的内容报错，就先执行 `finally` 中的内容，然后抛出异常
- 如果 `finally` 中有 `break`，`continue`，`return` 异常就不会被抛出
```bash
>>> def f():
...     try:
...         open("a")
...         print('try')
...         return '1'
...     except Exception:
...         raise RuntimeError("unable to handle error")
...     finally:
...         print('finally here')
...         return '2'
...
>>> f()
finally here
'2'
```

- 如果 `try` 中有 `break`，`continue`，`return` 。`finally` 就会现在这些语句之前执行
- 如果 `finally` 中有 `return` 返回值不是 `try` 中的 `return` 而是 `finally` 中的
```bash
>>> def bool_return():
...     try:
...         return True
...     finally:
...         return False
...
>>> bool_return()
False
```
## 8.8 Predefined Clean-up Actions
`with`可以确保 IO Stream 被正常关闭，等价于 JAVA 中的 `try...with`
## 8.9 Raising and Handling Multiple Unrelated Exceptions
> Python 3.11 新增功能

如果需要捕获一组 Exceptions 可以使用 `ExceptonGroup`
```bash
>>> def f():
...     excs = [OSError('error 1'), SystemError('error 2')]
...     raise ExceptionGroup('there were problems', excs)
...
>>> try:
...     f()
... except Exception as e:
...     print(f'caught {type(e)}: e')
...
caught <class 'NameError'>: e
```
可以使用 `except*` 替代 `except` 来捕获 `ExceptionGroup` 中特定的异常
```bash

def f():
    raise ExceptionGroup("group1",
                         [OSError(1),
                          SystemError(2)])

try:
    f()
except* OSError as e:
    print("There were OSErrors")
except* SystemError as e:
    print("There were SystemErrors")
```
## 8.10 Enriching Exceptions with Notes
> Python 3.11 新增功能

具体参考官方文档
```bash
try:
    raise TypeError('bad type')
except Exception as e:
    e.add_note('Add some information')
    e.add_note('Add some more information')
    raise

Traceback (most recent call last):
  File "<stdin>", line 2, in <module>
TypeError: bad type
Add some information
Add some more information
```
